<?xml version="1.0" ?>
<!-- =================================================================================== -->
<!-- |    This document was autogenerated by xacro from hsmakata.urdf.xacro            | -->
<!-- |    EDITING THIS FILE BY HAND IS NOT RECOMMENDED                                 | -->
<!-- =================================================================================== -->
<robot name="hsmakata" xmlns:controller="http://playerstage.sourceforge.net/gazebo/xmlschema/#controller" xmlns:sensor="http://playerstage.sourceforge.net/gazebo/xmlschema/#sensor" xmlns:xacro="http://ros.org/wiki/xacro">
  <transmission name="katana_motor1_pan_trans">
    <type>transmission_interface/SimpleTransmission</type>
    <joint name="katana_motor1_pan_joint"/>
    <actuator name="katana_motor1_pan_motor">
      <hardwareInterface>EffortJointInterface</hardwareInterface>
      <mechanicalReduction>1</mechanicalReduction>
    </actuator>
  </transmission>
  <transmission name="katana_motor2_lift_trans">
    <type>transmission_interface/SimpleTransmission</type>
    <joint name="katana_motor2_lift_joint"/>
    <actuator name="katana_motor2_lift_motor">
      <hardwareInterface>EffortJointInterface</hardwareInterface>
      <mechanicalReduction>1</mechanicalReduction>
    </actuator>
  </transmission>
  <transmission name="katana_motor3_lift_trans">
    <type>transmission_interface/SimpleTransmission</type>
    <joint name="katana_motor3_lift_joint"/>
    <actuator name="katana_motor3_lift_motor">
      <hardwareInterface>EffortJointInterface</hardwareInterface>
      <mechanicalReduction>1</mechanicalReduction>
    </actuator>
  </transmission>
  <transmission name="katana_motor4_lift_trans">
    <type>transmission_interface/SimpleTransmission</type>
    <joint name="katana_motor4_lift_joint"/>
    <actuator name="katana_motor4_lift_motor">
      <hardwareInterface>EffortJointInterface</hardwareInterface>
      <mechanicalReduction>1</mechanicalReduction>
    </actuator>
  </transmission>
  <transmission name="katana_motor5_wrist_roll_trans">
    <type>transmission_interface/SimpleTransmission</type>
    <joint name="katana_motor5_wrist_roll_joint"/>
    <actuator name="katana_motor5_wrist_roll_motor">
      <hardwareInterface>EffortJointInterface</hardwareInterface>
      <mechanicalReduction>1</mechanicalReduction>
    </actuator>
  </transmission>
  <transmission name="katana_r_finger_trans">
    <type>transmission_interface/SimpleTransmission</type>
    <joint name="katana_r_finger_joint"/>
    <actuator name="katana_r_finger_motor">
      <hardwareInterface>EffortJointInterface</hardwareInterface>
      <mechanicalReduction>1</mechanicalReduction>
    </actuator>
  </transmission>
  <transmission name="katana_l_finger_trans">
    <type>transmission_interface/SimpleTransmission</type>
    <joint name="katana_l_finger_joint"/>
    <actuator name="katana_l_finger_motor">
      <hardwareInterface>EffortJointInterface</hardwareInterface>
      <mechanicalReduction>1</mechanicalReduction>
    </actuator>
  </transmission>
  <transmission name="katana_motor1_pan_trans">
    <type>transmission_interface/SimpleTransmission</type>
    <joint name="katana_motor1_pan_joint"/>
    <actuator name="katana_motor1_pan_motor">
      <hardwareInterface>EffortJointInterface</hardwareInterface>
      <mechanicalReduction>1</mechanicalReduction>
    </actuator>
  </transmission>
  <transmission name="katana_motor2_lift_trans">
    <type>transmission_interface/SimpleTransmission</type>
    <joint name="katana_motor2_lift_joint"/>
    <actuator name="katana_motor2_lift_motor">
      <hardwareInterface>EffortJointInterface</hardwareInterface>
      <mechanicalReduction>1</mechanicalReduction>
    </actuator>
  </transmission>
  <transmission name="katana_motor3_lift_trans">
    <type>transmission_interface/SimpleTransmission</type>
    <joint name="katana_motor3_lift_joint"/>
    <actuator name="katana_motor3_lift_motor">
      <hardwareInterface>EffortJointInterface</hardwareInterface>
      <mechanicalReduction>1</mechanicalReduction>
    </actuator>
  </transmission>
  <transmission name="katana_motor4_lift_trans">
    <type>transmission_interface/SimpleTransmission</type>
    <joint name="katana_motor4_lift_joint"/>
    <actuator name="katana_motor4_lift_motor">
      <hardwareInterface>EffortJointInterface</hardwareInterface>
      <mechanicalReduction>1</mechanicalReduction>
    </actuator>
  </transmission>
  <transmission name="katana_motor5_wrist_roll_trans">
    <type>transmission_interface/SimpleTransmission</type>
    <joint name="katana_motor5_wrist_roll_joint"/>
    <actuator name="katana_motor5_wrist_roll_motor">
      <hardwareInterface>EffortJointInterface</hardwareInterface>
      <mechanicalReduction>1</mechanicalReduction>
    </actuator>
  </transmission>
  <transmission name="katana_r_finger_trans">
    <type>transmission_interface/SimpleTransmission</type>
    <joint name="katana_r_finger_joint"/>
    <actuator name="katana_r_finger_motor">
      <hardwareInterface>EffortJointInterface</hardwareInterface>
      <mechanicalReduction>1</mechanicalReduction>
    </actuator>
  </transmission>
  <transmission name="katana_l_finger_trans">
    <type>transmission_interface/SimpleTransmission</type>
    <joint name="katana_l_finger_joint"/>
    <actuator name="katana_l_finger_motor">
      <hardwareInterface>EffortJointInterface</hardwareInterface>
      <mechanicalReduction>1</mechanicalReduction>
    </actuator>
  </transmission>
  <gazebo>
    <plugin filename="libgazebo_ros_control.so" name="gazebo_ros_control">
      <robotSimType>gazebo_ros_control/DefaultRobotHWSim</robotSimType>
    </plugin>
    <!-- gripper controller -->
    <plugin filename="libgazebo_ros_katana_gripper.so" name="katana_gripper_controller">
      <alwaysOn>true</alwaysOn>
      <node_namespace>katana</node_namespace>
      <r_finger_joint>katana_r_finger_joint</r_finger_joint>
      <l_finger_joint>katana_l_finger_joint</l_finger_joint>
      <updateRate>1000.0</updateRate>
      <max_torque>0.5</max_torque>
    </plugin>
    <!-- a formal implementation of grasp hack in gazebo with fixed joint -->
    <gripper name="katana_gripper_grasp_hack">
      <grasp_check>
        <attach_steps>20</attach_steps>
        <detach_steps>40</detach_steps>
        <min_contact_count>2</min_contact_count>
      </grasp_check>
      <gripper_link>katana_r_finger_link</gripper_link>
      <gripper_link>katana_l_finger_link</gripper_link>
      <palm_link>katana_gripper_link</palm_link>
    </gripper>
  </gazebo>
  <gazebo reference="katana_base_link">
    <material value="Gazebo/Grey"/>
  </gazebo>
  <gazebo reference="katana_motor1_pan_link">
    <material value="Gazebo/Grey"/>
    <turnGravityOff>true</turnGravityOff>
  </gazebo>
  <gazebo reference="katana_motor2_lift_link">
    <material value="Gazebo/Grey"/>
    <turnGravityOff>true</turnGravityOff>
  </gazebo>
  <gazebo reference="katana_motor3_lift_link">
    <material value="Gazebo/Grey"/>
    <turnGravityOff>true</turnGravityOff>
  </gazebo>
  <gazebo reference="katana_motor4_lift_link">
    <material value="Gazebo/Grey"/>
    <turnGravityOff>true</turnGravityOff>
  </gazebo>
  <gazebo reference="katana_motor5_wrist_roll_link">
    <material value="Gazebo/Grey"/>
    <turnGravityOff>true</turnGravityOff>
  </gazebo>
  <gazebo reference="katana_gripper_link">
    <material value="Gazebo/Grey"/>
    <turnGravityOff>true</turnGravityOff>
  </gazebo>
  <gazebo reference="katana_r_finger_link">
    <material value="Gazebo/Grey"/>
    <turnGravityOff>true</turnGravityOff>
  </gazebo>
  <gazebo reference="katana_l_finger_link">
    <material value="Gazebo/Grey"/>
    <turnGravityOff>true</turnGravityOff>
  </gazebo>
  <gazebo reference="katana_motor1_pan_joint">
    <initial_joint_position>-3.022</initial_joint_position>
  </gazebo>
  <gazebo reference="katana_motor2_lift_joint">
    <initial_joint_position>2.163</initial_joint_position>
  </gazebo>
  <gazebo reference="katana_motor3_lift_joint">
    <initial_joint_position>-2.207</initial_joint_position>
  </gazebo>
  <gazebo reference="katana_motor4_lift_joint">
    <initial_joint_position>-2.026</initial_joint_position>
  </gazebo>
  <gazebo reference="katana_motor5_wrist_roll_joint">
    <initial_joint_position>-2.990</initial_joint_position>
  </gazebo>
  <gazebo reference="katana_r_finger_joint">
    <initial_joint_position>0.3</initial_joint_position>
  </gazebo>
  <gazebo reference="katana_l_finger_joint">
    <initial_joint_position>0.3</initial_joint_position>
  </gazebo>
  <link name="katana_base_link">
    <visual>
      <origin rpy="0 0 0" xyz="0 0 0"/>
      <geometry>
        <mesh filename="package://katana_description/meshes/katana/katana_base_link.stl"/>
      </geometry>
      <material name="grey">
        <color rgba="0.8 0.8 0.8 1"/>
      </material>
    </visual>
    <collision>
      <origin rpy="0 0 0" xyz="0 0 0"/>
      <geometry>
        <mesh filename="package://katana_description/meshes/katana/convex/katana_base_link_convex.stl"/>
      </geometry>
    </collision>
    <inertial>
      <mass value="1.4047990875"/>
      <origin xyz="-0.000327 0.000908 0.058457"/>
      <inertia ixx="0.003000703" ixy="0.000000864" ixz="-0.000011312" iyy="0.002974822" iyz="0.000036294" izz="0.001434739"/>
    </inertial>
  </link>
  <joint name="katana_motor1_pan_joint" type="revolute">
    <!-- Joint 1 in Katana Manual -->
    <parent link="katana_base_link"/>
    <child link="katana_motor1_pan_link"/>
    <origin rpy="0 0 0" xyz="0 0 0.2015"/>
    <axis xyz="0 0 1"/>
    <limit effort="1.5" lower="-3.025528" upper="2.891097" velocity="2.208932"/>
  </joint>
  <link name="katana_motor1_pan_link">
    <visual>
      <origin rpy="0 0 0" xyz="0 0 -0.2015"/>
      <geometry>
        <mesh filename="package://katana_description/meshes/katana/katana_motor1_pan_link.stl"/>
      </geometry>
      <material name="grey"/>
    </visual>
    <collision>
      <origin rpy="0 0 0" xyz="0 0 -0.2015"/>
      <geometry>
        <mesh filename="package://katana_description/meshes/katana/convex/katana_motor1_pan_link_convex.stl"/>
      </geometry>
    </collision>
    <inertial>
      <mass value="0.74793301875"/>
      <origin xyz="-0.000410 -0.001285 -0.016774"/>
      <inertia ixx="0.001737241" ixy="0.000000421" ixz="0.000000650" iyy="0.000998782" iyz="0.000016114" izz="0.001349170"/>
    </inertial>
  </link>
  <joint name="katana_motor2_lift_joint" type="revolute">
    <!-- Joint 2 in Katana Manual -->
    <parent link="katana_motor1_pan_link"/>
    <child link="katana_motor2_lift_link"/>
    <origin rpy="1.57079632679 0 0" xyz="0 0 0"/>
    <axis xyz="0 0 1"/>
    <limit effort="0.6" lower="-0.135228" upper="2.168572" velocity="1.190799"/>
  </joint>
  <link name="katana_motor2_lift_link">
    <visual>
      <origin rpy="-1.57079632679 0 0" xyz="0 0 0"/>
      <geometry>
        <mesh filename="package://katana_description/meshes/katana/katana_motor2_lift_link.stl"/>
      </geometry>
      <!-- <geometry>
          <cylinder length="${link2_length}" radius="0.02"/>
        </geometry>
        <origin rpy="0 ${-M_PI/2} 0" xyz="${link2_length/2} 0 0" /> -->
      <material name="grey"/>
    </visual>
    <collision>
      <origin rpy="-1.57079632679 0 0" xyz="0 0 0"/>
      <geometry>
        <mesh filename="package://katana_description/meshes/katana/convex/katana_motor2_lift_link_convex.stl"/>
      </geometry>
    </collision>
    <inertial>
      <mass value="0.80174941875"/>
      <origin xyz="0.092420 0.005283 0.000172"/>
      <inertia ixx="0.000478252" ixy="0.000081166" ixz="0.000003961" iyy="0.004314636" iyz="0.000000332" izz="0.004625444"/>
    </inertial>
  </link>
  <joint name="katana_motor3_lift_joint" type="revolute">
    <!-- Joint 3 in Katana Manual -->
    <parent link="katana_motor2_lift_link"/>
    <child link="katana_motor3_lift_link"/>
    <origin rpy="0 0 0" xyz="0.19 0 0"/>
    <axis xyz="0 0 1"/>
    <!-- unexplicably, the measured velocity limit of this motor is exactly half of what vel_enc2rad(180) says -->
    <limit effort="0.25" lower="-2.221804" upper="2.054223" velocity="1.190799"/>
  </joint>
  <link name="katana_motor3_lift_link">
    <visual>
      <origin rpy="-1.57079632679 0 0" xyz="0 0 0"/>
      <geometry>
        <mesh filename="package://katana_description/meshes/katana/katana_motor3_lift_link.stl"/>
      </geometry>
      <!--<geometry>
          <cylinder length="${link3_length}" radius="0.02"/>
        </geometry>
        <origin rpy="0 ${-M_PI/2} 0" xyz="${link3_length/2} 0 0" />-->
      <material name="grey"/>
    </visual>
    <collision>
      <origin rpy="-1.57079632679 0 0" xyz="0 0 0"/>
      <geometry>
        <mesh filename="package://katana_description/meshes/katana/convex/katana_motor3_lift_link_convex.stl"/>
      </geometry>
    </collision>
    <inertial>
      <mass value="0.79241664375"/>
      <origin xyz="0.058036 0.008963 -0.000187"/>
      <inertia ixx="0.001156089" ixy="0.000112877" ixz="-0.000004398" iyy="0.002305646" iyz="-0.000000036" izz="0.003128648"/>
    </inertial>
  </link>
  <joint name="katana_motor4_lift_joint" type="revolute">
    <!-- Joint 4 in Katana Manual -->
    <parent link="katana_motor3_lift_link"/>
    <child link="katana_motor4_lift_link"/>
    <origin rpy="3.14159265359 0 0" xyz="0.139 0 0"/>
    <axis xyz="0 0 1"/>
    <limit effort="0.1" lower="-2.033309" upper="1.876133" velocity="2.208932"/>
  </joint>
  <link name="katana_motor4_lift_link">
    <visual>
      <origin rpy="1.57079632679 0 0" xyz="0 0 0"/>
      <geometry>
        <mesh filename="package://katana_description/meshes/katana/katana_motor4_lift_link.stl"/>
      </geometry>
      <!-- <geometry>
          <cylinder length="${link4_length}" radius="0.02"/>
        </geometry>
        <origin rpy="0 ${-M_PI/2} 0" xyz="${link4_length/2} 0 0" /> -->
      <material name="grey"/>
    </visual>
    <collision>
      <origin rpy="1.57079632679 0 0" xyz="0 0 0"/>
      <geometry>
        <mesh filename="package://katana_description/meshes/katana/convex/katana_motor4_lift_link_convex.stl"/>
      </geometry>
    </collision>
    <inertial>
      <mass value="0.69149323125"/>
      <origin xyz="0.050401 0.005807 0.000000"/>
      <inertia ixx="0.000765999" ixy="0.000045260" ixz="-0.000001210" iyy="0.001504115" iyz="0.000000147" izz="0.001887277"/>
    </inertial>
  </link>
  <joint name="katana_motor5_wrist_roll_joint" type="revolute">
    <!-- Joint 5 in Katana Manual -->
    <parent link="katana_motor4_lift_link"/>
    <child link="katana_motor5_wrist_roll_link"/>
    <origin rpy="1.57079632679 0 -1.57079632679" xyz="0.1523 0 0"/>
    <axis xyz="0 0 1"/>
    <limit effort="0.01" lower="-2.993240" upper="2.870985" velocity="2.208932"/>
  </joint>
  <link name="katana_motor5_wrist_roll_link">
    <visual>
      <origin rpy="0 3.14159265359 0" xyz="0 0 0"/>
      <geometry>
        <mesh filename="package://katana_description/meshes/katana/katana_motor5_wrist_roll_link.stl"/>
      </geometry>
      <!--<geometry>
          <cylinder length="${link5_length}" radius="0.02"/>
        </geometry>
        <origin rpy="0 ${-M_PI/2} 0" xyz="${link5_length/2} 0 0" />-->
      <material name="grey"/>
    </visual>
    <collision>
      <origin rpy="0 3.14159265359 0" xyz="0 0 0"/>
      <geometry>
        <mesh filename="package://katana_description/meshes/katana/convex/katana_motor5_wrist_roll_link_convex.stl"/>
      </geometry>
    </collision>
    <inertial>
      <mass value="0.25622555625"/>
      <origin xyz="-0.003140899 0.000013920 0.001680144"/>
      <inertia ixx="0.000120481" ixy="0.000000015" ixz="-0.000001089" iyy="0.000132130" iyz="-0.000000124" izz="0.000093522"/>
    </inertial>
  </link>
  <joint name="katana_gripper_joint" type="fixed">
    <parent link="katana_motor5_wrist_roll_link"/>
    <child link="katana_gripper_link"/>
    <origin rpy="0 1.57079632679 0" xyz="0 0 -0.0323"/>
  </joint>
  <link name="katana_gripper_link">
    <visual>
      <origin rpy="0 3.14159265359 0" xyz="0 0 0"/>
      <geometry>
        <mesh filename="package://katana_description/meshes/katana/katana_gripper_link.stl"/>
      </geometry>
      <material name="grey"/>
    </visual>
    <collision>
      <origin rpy="0 3.14159265359 0" xyz="0 0 0"/>
      <geometry>
        <mesh filename="package://katana_description/meshes/katana/convex/katana_gripper_link_convex.stl"/>
      </geometry>
    </collision>
    <inertial>
      <mass value="0.0552136183596"/>
      <origin xyz="-0.014379 -0.000000 0.000006"/>
      <inertia ixx="0.000011468" ixy="0.000000000" ixz="0.000000007" iyy="0.000013830" iyz="0.000000000" izz="0.000011290"/>
    </inertial>
  </link>
  <joint name="katana_r_finger_joint" type="revolute">
    <parent link="katana_gripper_link"/>
    <child link="katana_r_finger_link"/>
    <origin rpy="0 0 0" xyz="0.034 0 0"/>
    <axis xyz="0 0 1"/>
    <limit effort="0.5" lower="-0.44" upper="0.30" velocity="0.718834"/>
  </joint>
  <link name="katana_r_finger_link">
    <visual>
      <origin rpy="0 3.14159265359 0" xyz="0 0 0"/>
      <geometry>
        <mesh filename="package://katana_description/meshes/katana/katana_gripper_r_finger.stl"/>
      </geometry>
      <material name="grey"/>
    </visual>
    <collision>
      <origin rpy="0 3.14159265359 0" xyz="0 0 0"/>
      <geometry>
        <mesh filename="package://katana_description/meshes/katana/convex/katana_gripper_r_finger_convex.stl"/>
      </geometry>
    </collision>
    <inertial>
      <mass value="0.0251722230462"/>
      <origin xyz="0.001784 0.025167 -.001603"/>
      <inertia ixx="0.000005990" ixy="0.000008473" ixz="0.000001448" iyy="0.000019757" iyz="-0.000000996" izz="0.000023588"/>
    </inertial>
  </link>
  <joint name="katana_l_finger_joint" type="revolute">
    <parent link="katana_gripper_link"/>
    <child link="katana_l_finger_link"/>
    <origin rpy="3.14159265359 0 0" xyz="0.034 0 0"/>
    <axis xyz="0 0 1"/>
    <limit effort="0.5" lower="-0.44" upper="0.30" velocity="0.718834"/>
  </joint>
  <link name="katana_l_finger_link">
    <visual>
      <origin rpy="0 3.14159265359 0" xyz="0 0 0"/>
      <geometry>
        <mesh filename="package://katana_description/meshes/katana/katana_gripper_l_finger.stl"/>
      </geometry>
      <material name="grey"/>
    </visual>
    <collision>
      <origin rpy="0 3.14159265359 0" xyz="0 0 0"/>
      <geometry>
        <mesh filename="package://katana_description/meshes/katana/convex/katana_gripper_l_finger_convex.stl"/>
      </geometry>
    </collision>
    <inertial>
      <mass value="0.0251722230462"/>
      <origin xyz="0.001784 0.025167 -.001603"/>
      <inertia ixx="0.000005990" ixy="0.000008473" ixz="0.000001448" iyy="0.000019757" iyz="-0.000000996" izz="0.000023588"/>
    </inertial>
  </link>
  <joint name="katana_gripper_tool_frame_joint" type="fixed">
    <parent link="katana_motor5_wrist_roll_link"/>
    <child link="katana_gripper_tool_frame"/>
    <origin rpy="0 1.57079632679 0" xyz="0 0 -0.1505"/>
  </joint>
  <link name="katana_gripper_tool_frame">
    <!-- This is the coordinate system of the tool (this is the position
         used in IK etc., relative to the base frame); there is no actual
         arm part attached to this link -->
  </link>
  <joint name="katana_base_frame_joint" type="fixed">
    <parent link="katana_base_link"/>
    <child link="katana_base_frame"/>
    <origin rpy="0 0 0" xyz="0 0 0.2015"/>
  </joint>
  <link name="katana_base_frame">
    <!-- This is the reference coordinate system of the arm (the KNI kinematics are specified
         in this frame); there is no actual arm part attached to this link -->
  </link>
  <!-- **************************** -->
  <!-- ** base_link to base_frame * -->
  <!-- **************************** -->
  <link name="base_link"/>
  <link name="base_frame">
    <visual>
      <origin rpy="0 0 0" xyz="0 0 0"/>
      <geometry>
        <mesh filename="package://hsmakata_description/meshes/base_frame.stl"/>
      </geometry>
      <material name="grey">
        <color rgba="0.3 0.3 0.3 1"/>
      </material>
    </visual>
  </link>
  <joint name="base_frame_joint" type="fixed">
    <parent link="base_link"/>
    <child link="base_frame"/>
    <origin rpy="0 0 0" xyz="0.0 0.0 0.0025"/>
  </joint>
  <!-- **************************** -->
  <!-- ** base_link to base_frame * -->
  <!-- **************************** -->
  <link name="table_frame">
    <visual>
      <origin rpy="0 0 0" xyz="0 0 0"/>
      <geometry>
        <mesh filename="package://hsmakata_description/meshes/table.stl"/>
      </geometry>
      <material name="violet">
        <color rgba="0.8 0.0 0.8 1"/>
      </material>
    </visual>
  </link>
  <joint name="table_frame_joint" type="fixed">
    <parent link="base_link"/>
    <child link="table_frame"/>
    <origin rpy="0 0 0" xyz="0.675 0.0 0.0"/>
  </joint>
  <!-- **************************** -->
  <!-- * base_frame to dummy_link * -->
  <!-- **************************** -->
  <link name="dummy_link"/>
  <joint name="dummy_joint" type="fixed">
    <parent link="base_frame"/>
    <child link="dummy_link"/>
    <origin rpy="0 0 0" xyz="0.0 0.0 0.235"/>
  </joint>
  <!-- **************************** -->
  <!-- * dummy_link to sick_link ** -->
  <!-- **************************** -->
  <joint name="sick_joint" type="fixed">
    <parent link="dummy_link"/>
    <child link="sick_link"/>
    <origin rpy="0 0 0" xyz="0.12 0 -0.17"/>
  </joint>
  <link name="sick_link">
    <visual>
      <geometry>
        <mesh filename="package://hsmakata_description/meshes/sick_lms-200.stl"/>
      </geometry>
      <material name="blue">
        <color rgba="0.0 0.0 0.8 1"/>
      </material>
    </visual>
  </link>
  <!-- **************************** -->
  <!-- * dummy_link to kata_plate_link * -->
  <!-- **************************** -->
  <link name="kata_plate_link">
    <visual>
      <geometry>
        <mesh filename="package://hsmakata_description/meshes/katana_base_plate.stl"/>
      </geometry>
      <material name="grey">
        <color rgba="0.5 0.5 0.5 1"/>
      </material>
    </visual>
  </link>
  <joint name="kata_plate_joint" type="fixed">
    <parent link="dummy_link"/>
    <child link="kata_plate_link"/>
    <origin rpy="0 0 0" xyz="0.054 0 0.0"/>
  </joint>
  <!-- **************************** -->
  <!-- *** kata_plate_link to Katana Arm *** -->
  <!-- **************************** -->
  <joint name="base_link_to_katana" type="fixed">
    <parent link="kata_plate_link"/>
    <child link="katana_base_link"/>
    <origin rpy="0 0 0" xyz="0 0 0"/>
  </joint>
  <!-- **************************** -->
  <!-- ***** dummy_link to pole_link** -->
  <!-- **************************** -->
  <link name="pole_link">
    <visual>
      <geometry>
        <mesh filename="package://hsmakata_description/meshes/pole2.stl"/>
      </geometry>
      <material name="grey">
        <color rgba="0.5 0.5 0.5 1"/>
      </material>
    </visual>
  </link>
  <joint name="pole_joint" type="fixed">
    <parent link="dummy_link"/>
    <child link="pole_link"/>
    <origin rpy="0 0 0" xyz="-0.195 0.0 0"/>
  </joint>
  <!-- **************************** -->
  <!-- ***** pole_link to kinect_holder_link ** -->
  <!-- **************************** -->
  <link name="kinect_holder_link">
    <visual>
      <origin rpy="0 0 0" xyz="0 0 0"/>
      <geometry>
        <box size="0.11 0.08 0.06"/>
      </geometry>
      <material name="grey">
        <color rgba="0.5 0.5 0.5 1"/>
      </material>
    </visual>
    <inertial>
      <mass value="0.01"/>
      <origin rpy="0 0 0" xyz="0.03 0 0"/>
      <inertia ixx="2.54166565e-05" ixy="0.0" ixz="0.0" iyy="6.666664e-06" iyz="0.0" izz="2.94166549e-05"/>
    </inertial>
  </link>
  <joint name="kinect_holder_joint" type="fixed">
    <parent link="pole_link"/>
    <child link="kinect_holder_link"/>
    <origin rpy="0 0 0" xyz="0.03 0.0 0.738"/>
  </joint>
  <!-- **************************** -->
  <!-- ***** kinect_holder_link to kinect_link ** -->
  <!-- **************************** -->
  <link name="kinect_link">
    <visual>
      <origin rpy="0 0 0" xyz="0.0 0 0"/>
      <geometry>
        <mesh filename="package://pr2_description/meshes/sensors/kinect_v0/kinect.dae" scale="0.001 0.001 0.001"/>
      </geometry>
    </visual>
    <collision>
      <origin rpy="0 0 0" xyz="-0.0315 0 -0.017"/>
      <geometry>
        <box size="0.0730 0.2760 0.0720"/>
      </geometry>
    </collision>
    <inertial>
      <mass value="0.43"/>
      <origin xyz="0 0 0"/>
      <inertia ixx="0.00291539883384" ixy="0.0" ixz="0.0" iyy="0.000376715682647" iyz="0.0" izz="0.0029205946651"/>
    </inertial>
  </link>
  <!-- kinect -25 effektiv 21.77 rad=0.38 -->
  <!-- origin rpy="0 0.38 0" xyz="0.06 -0.02 0.075" -->
  <joint name="kinect_joint" type="fixed">
    <parent link="kinect_holder_link"/>
    <child link="kinect_link"/>
    <origin rpy="0 0.435 0" xyz="0.065 -0.015 0.085"/>
    <limit effort="1000.0" lower="-1.57079632679" upper="1.57079632679" velocity="2.0"/>
  </joint>
  <joint name="kinect_depth_joint" type="fixed">
    <origin rpy="0 0 0" xyz="0 -0.028 0"/>
    <parent link="kinect_link"/>
    <child link="kinect_depth_frame"/>
  </joint>
  <link name="kinect_depth_frame">
    <inertial>
      <mass value="0.000001"/>
      <origin xyz="0 0 0"/>
      <inertia ixx="0.0001" ixy="0.0" ixz="0.0" iyy="0.0001" iyz="0.0" izz="0.0001"/>
    </inertial>
  </link>
  <joint name="kinect_depth_optical_joint" type="fixed">
    <origin rpy="-1.57079632679 0 -1.57079632679" xyz="0 0 0"/>
    <parent link="kinect_depth_frame"/>
    <child link="kinect_depth_optical_frame"/>
  </joint>
  <link name="kinect_depth_optical_frame">
    <inertial>
      <mass value="0.000001"/>
      <origin xyz="0 0 0"/>
      <inertia ixx="0.0001" ixy="0.0" ixz="0.0" iyy="0.0001" iyz="0.0" izz="0.0001"/>
    </inertial>
  </link>
  <joint name="kinect_rgb_joint" type="fixed">
    <origin rpy="0 0 0" xyz="0 -0.005 0"/>
    <parent link="kinect_link"/>
    <child link="kinect_rgb_frame"/>
  </joint>
  <link name="kinect_rgb_frame">
    <inertial>
      <mass value="0.000001"/>
      <origin xyz="0 0 0"/>
      <inertia ixx="0.0001" ixy="0.0" ixz="0.0" iyy="0.0001" iyz="0.0" izz="0.0001"/>
    </inertial>
  </link>
  <joint name="kinect_rgb_optical_joint" type="fixed">
    <origin rpy="-1.57079632679 0 -1.57079632679" xyz="0 0 0"/>
    <parent link="kinect_rgb_frame"/>
    <child link="kinect_rgb_optical_frame"/>
  </joint>
  <link name="kinect_rgb_optical_frame">
    <inertial>
      <mass value="0.000001"/>
      <origin xyz="0 0 0"/>
      <inertia ixx="0.0001" ixy="0.0" ixz="0.0" iyy="0.0001" iyz="0.0" izz="0.0001"/>
    </inertial>
  </link>
  <link name="cup1">
    <visual>
      <geometry>
        <cylinder length="0.096" radius="0.036"/>
      </geometry>
      <material name="green">
        <color rgba="0 1 0 0.5"/>
      </material>
    </visual>
  </link>
  <joint name="base_link_to_cup1" type="fixed">
    <parent link="base_link"/>
    <child link="cup1"/>
    <origin rpy="0 0 0" xyz="0.55 0.2 0.5"/>
  </joint>
  <link name="cup2">
    <visual>
      <geometry>
        <cylinder length="0.096" radius="0.036"/>
      </geometry>
      <material name="red">
        <color rgba="1 0 0 0.5"/>
      </material>
    </visual>
  </link>
  <joint name="base_link_to_cup2" type="fixed">
    <parent link="base_link"/>
    <child link="cup2"/>
    <origin rpy="0 0 0" xyz="0.65 -0.2 0.5"/>
  </joint>
</robot>

