<?xml version="1.0" encoding="UTF-8"?>
<robot xmlns:controller="http://playerstage.sourceforge.net/gazebo/xmlschema/#controller" xmlns:sensor="http://playerstage.sourceforge.net/gazebo/xmlschema/#sensor" xmlns:xacro="http://ros.org/wiki/xacro" name="katana">
  <xacro:include filename="$(find katana_description)/urdf/transmissions.urdf.xacro" />
  <xacro:include filename="$(find katana_description)/urdf/transmissions.urdf.xacro" />
  
<link name="base_link" />

<joint name="base_link_base_plate" type="fixed">
    <parent link="base_link" />
    <child link="base_plate" />
    <origin rpy="0 0 0" xyz="0 0 0" />
</joint>

  <link name="base_plate">
    <visual>
      <origin rpy="0 0 0" xyz="0 0 0"/>
      <geometry>
        <mesh filename="package://hsmakata_description/meshes/base_plate.stl"/>
      </geometry>
      <material name="grey">
        <color rgba="0.5 0.5 0.5 1" />
      </material>
    </visual>
  </link>
  <!-- **************************** -->
  <!-- *** Neuronics Katana Arm *** -->
  <!-- **************************** -->
  <xacro:include filename="$(find katana_description)/urdf/katana_400_6m180.urdf.xacro" />
  <joint name="base_link_to_katana" type="fixed">
    <parent link="base_plate" />
    <child link="katana_base_link" />
    <origin rpy="0 0 0" xyz="0.12 0 0" />
  </joint>
  <!-- **************************** -->
  <!-- ***** Pole and Kinect ****** -->
  <!-- **************************** -->
  <joint name="base_link_to_pole" type="fixed">
    <parent link="base_plate" />
    <child link="pole" />
    <origin rpy="0 0 0" xyz="-0.12 0 0.7" />
  </joint>
  <link name="pole">
    <visual>
      <geometry>
       <mesh filename="package://hsmakata_description/meshes/pole.stl"/>
      </geometry>
      <material name="grey">
        <color rgba="0.5 0.5 0.5 1" />
      </material>
    </visual>
  </link>
  <joint name="kinect_pitch_joint" type="revolute">
    <parent link="pole" />
    <child link="kinect_pitch_link" />
    <origin rpy="0 0 0" xyz="0 0 0.4" />
    <axis xyz="0 1 0" />
    <limit effort="1000.0" lower="-1.57079632679" upper="1.57079632679" velocity="2.0" />
  </joint>
  <link name="kinect_pitch_link">
    <visual>
      <origin rpy="0 0 0" xyz="0.03 0 -0.05" />
      <geometry>
        <box size="0.08 0.17 0.04" />
      </geometry>
      <material name="grey">
        <color rgba="0.5 0.5 0.5 1" />
      </material>
    </visual>
    <collision>
      <origin rpy="0 0 0" xyz="0.03 0 0" />
      <geometry>
        <box size="0.08 0.17 0.04" />
      </geometry>
    </collision>
    <inertial>
      <mass value="0.01" />
      <origin rpy="0 0 0" xyz="0.03 0 0" />
      <inertia ixx="2.54166565e-05" ixy="0.0" ixz="0.0" iyy="6.666664e-06" iyz="0.0" izz="2.94166549e-05" />
    </inertial>
  </link>
  <link name="kinect_link">
    <visual>
      <origin rpy="0 0 0" xyz="0 0 0" />
      <geometry>
        <mesh filename="package://pr2_description/meshes/sensors/kinect_v0/kinect.dae" scale="0.001 0.001 0.001" />
      </geometry>
    </visual>
    <collision>
      <origin rpy="0 0 0" xyz="-0.0315 0 -0.017" />
      <geometry>
        <box size="0.0730 0.2760 0.0720" />
      </geometry>
    </collision>
    <inertial>
      <mass value="0.43" />
      <origin xyz="0 0 0" />
      <inertia ixx="0.00291539883384" ixy="0.0" ixz="0.0" iyy="0.000376715682647" iyz="0.0" izz="0.0029205946651" />
    </inertial>
  </link>
  <joint name="calvin_kinect_joint" type="fixed">
    <parent link="kinect_pitch_link" />
    <child link="kinect_link" />
    <origin rpy="0 0.53 0" xyz="0.1 0.0 0.0" />
  </joint>

  <joint name="kinect_depth_joint" type="fixed">
    <origin rpy="0 0 0" xyz="0 0.018 0"/>
    <parent link="kinect_link"/>
    <child link="kinect_depth_frame"/>
  </joint>
  <link name="kinect_depth_frame">
    <inertial>
      <mass value="0.000001"/>
      <origin xyz="0 0 0"/>
      <inertia ixx="0.0001" ixy="0.0" ixz="0.0" iyy="0.0001" iyz="0.0" izz="0.0001"/>
    </inertial>
  </link>
  <joint name="kinect_depth_optical_joint" type="fixed">
    <origin rpy="-1.57079632679 0 -1.57079632679" xyz="0 0 0"/>
    <parent link="kinect_depth_frame"/>
    <child link="kinect_depth_optical_frame"/>
  </joint>
  <link name="kinect_depth_optical_frame">
    <inertial>
      <mass value="0.000001"/>
      <origin xyz="0 0 0"/>
      <inertia ixx="0.0001" ixy="0.0" ixz="0.0" iyy="0.0001" iyz="0.0" izz="0.0001"/>
    </inertial>
  </link>
  <gazebo reference="kinect_depth_frame">
    <sensor name="kinect_depth_frame_ir_sensor" type="depth">
      <always_on>true</always_on>
      <update_rate>1.0</update_rate>
      <camera>
        <horizontal_fov>0.994837673637</horizontal_fov>
        <image>
          <format>L8</format>
          <width>640</width>
          <height>480</height>
        </image>
        <clip>
          <near>0.01</near>
          <far>5</far>
        </clip>
      </camera>
      <plugin filename="libgazebo_ros_openni_kinect.so" name="kinect_depth_frame_controller">
        <alwaysOn>true</alwaysOn>
        <updateRate>1.0</updateRate>
        <cameraName>kinect_ir</cameraName>
        <imageTopicName>/kinect/depth/image_raw</imageTopicName>
        <cameraInfoTopicName>/kinect/depth/camera_info</cameraInfoTopicName>
        <depthImageTopicName>/kinect/depth/image_raw</depthImageTopicName>
        <depthImageCameraInfoTopicName>/kinect/depth/camera_info</depthImageCameraInfoTopicName>
        <pointCloudTopicName>/kinect/depth/points</pointCloudTopicName>
        <frameName>kinect_depth_optical_frame</frameName>
        <pointCloudCutoff>0.5</pointCloudCutoff>
        <distortionK1>0.00000001</distortionK1>
        <distortionK2>0.00000001</distortionK2>
        <distortionK3>0.00000001</distortionK3>
        <distortionT1>0.00000001</distortionT1>
        <distortionT2>0.00000001</distortionT2>
      </plugin>
    </sensor>
    <material value="Gazebo/Red"/>
  </gazebo>
  <joint name="kinect_rgb_joint" type="fixed">
    <origin rpy="0 0 0" xyz="0 -0.005 0"/>
    <parent link="kinect_link"/>
    <child link="kinect_rgb_frame"/>
  </joint>
  <link name="kinect_rgb_frame">
    <inertial>
      <mass value="0.000001"/>
      <origin xyz="0 0 0"/>
      <inertia ixx="0.0001" ixy="0.0" ixz="0.0" iyy="0.0001" iyz="0.0" izz="0.0001"/>
    </inertial>
  </link>
  <joint name="kinect_rgb_optical_joint" type="fixed">
    <origin rpy="-1.57079632679 0 -1.57079632679" xyz="0 0 0"/>
    <parent link="kinect_rgb_frame"/>
    <child link="kinect_rgb_optical_frame"/>
  </joint>
  <link name="kinect_rgb_optical_frame">
    <inertial>
      <mass value="0.000001"/>
      <origin xyz="0 0 0"/>
      <inertia ixx="0.0001" ixy="0.0" ixz="0.0" iyy="0.0001" iyz="0.0" izz="0.0001"/>
    </inertial>
  </link>
  <gazebo reference="kinect_rgb_frame">
    <sensor name="kinect_rgb_sensor" type="depth">
      <always_on>true</always_on>
      <update_rate>1.0</update_rate>
      <camera>
        <horizontal_fov>0.994837673637</horizontal_fov>
        <image>
          <format>R8G8B8</format>
          <width>640</width>
          <height>480</height>
        </image>
        <clip>
          <near>0.01</near>
          <far>5</far>
        </clip>
      </camera>
      <plugin filename="libgazebo_ros_openni_kinect.so" name="kinect_rgb_frame_controller">
        <alwaysOn>true</alwaysOn>
        <updateRate>1.0</updateRate>
        <cameraName>kinect_rgb</cameraName>
        <imageTopicName>/kinect/rgb/image_raw</imageTopicName>
        <cameraInfoTopicName>/kinect/rgb/camera_info</cameraInfoTopicName>
        <depthImageTopicName>/kinect/depth/image_raw</depthImageTopicName>
        <depthImageCameraInfoTopicName>/kinect/depth/camera_info</depthImageCameraInfoTopicName>
        <pointCloudTopicName>/kinect/depth_registered/points</pointCloudTopicName>
        <frameName>kinect_rgb_optical_frame</frameName>
        <pointCloudCutoff>0.5</pointCloudCutoff>
        <distortionK1>0.00000001</distortionK1>
        <distortionK2>0.00000001</distortionK2>
        <distortionK3>0.00000001</distortionK3>
        <distortionT1>0.00000001</distortionT1>
        <distortionT2>0.00000001</distortionT2>
      </plugin>
    </sensor>
    <material value="Gazebo/Red"/>
  </gazebo>
</robot>
