<?xml version="1.0" ?>
<!-- =================================================================================== -->
<!-- |    This document was autogenerated by xacro from hsmakata.urdf.xacro            | -->
<!-- |    EDITING THIS FILE BY HAND IS NOT RECOMMENDED                                 | -->
<!-- =================================================================================== -->
<robot name="hsmakata" xmlns:controller="http://playerstage.sourceforge.net/gazebo/xmlschema/#controller" xmlns:interface="http://playerstage.sourceforge.net/gazebo/xmlschema/#interface" xmlns:sensor="http://playerstage.sourceforge.net/gazebo/xmlschema/#sensor" xmlns:xacro="http://ros.org/wiki/xacro">
  <transmission name="katana_motor1_pan_trans">
    <type>transmission_interface/SimpleTransmission</type>
    <joint name="katana_motor1_pan_joint">
      <hardwareInterface>EffortJointInterface</hardwareInterface>
    </joint>
    <actuator name="katana_motor1_pan_motor">
      <hardwareInterface>EffortJointInterface</hardwareInterface>
      <mechanicalReduction>1</mechanicalReduction>
    </actuator>
  </transmission>
  <transmission name="katana_motor2_lift_trans">
    <type>transmission_interface/SimpleTransmission</type>
    <joint name="katana_motor2_lift_joint">
      <hardwareInterface>EffortJointInterface</hardwareInterface>
    </joint>
    <actuator name="katana_motor2_lift_motor">
      <hardwareInterface>EffortJointInterface</hardwareInterface>
      <mechanicalReduction>1</mechanicalReduction>
    </actuator>
  </transmission>
  <transmission name="katana_motor3_lift_trans">
    <type>transmission_interface/SimpleTransmission</type>
    <joint name="katana_motor3_lift_joint">
      <hardwareInterface>EffortJointInterface</hardwareInterface>
    </joint>
    <actuator name="katana_motor3_lift_motor">
      <hardwareInterface>EffortJointInterface</hardwareInterface>
      <mechanicalReduction>1</mechanicalReduction>
    </actuator>
  </transmission>
  <transmission name="katana_motor4_lift_trans">
    <type>transmission_interface/SimpleTransmission</type>
    <joint name="katana_motor4_lift_joint">
      <hardwareInterface>EffortJointInterface</hardwareInterface>
    </joint>
    <actuator name="katana_motor4_lift_motor">
      <hardwareInterface>EffortJointInterface</hardwareInterface>
      <mechanicalReduction>1</mechanicalReduction>
    </actuator>
  </transmission>
  <transmission name="katana_motor5_wrist_roll_trans">
    <type>transmission_interface/SimpleTransmission</type>
    <joint name="katana_motor5_wrist_roll_joint">
      <hardwareInterface>EffortJointInterface</hardwareInterface>
    </joint>
    <actuator name="katana_motor5_wrist_roll_motor">
      <hardwareInterface>EffortJointInterface</hardwareInterface>
      <mechanicalReduction>1</mechanicalReduction>
    </actuator>
  </transmission>
  <transmission name="katana_r_finger_trans">
    <type>transmission_interface/SimpleTransmission</type>
    <joint name="katana_r_finger_joint">
      <hardwareInterface>EffortJointInterface</hardwareInterface>
    </joint>
    <actuator name="katana_r_finger_motor">
      <hardwareInterface>EffortJointInterface</hardwareInterface>
      <mechanicalReduction>1</mechanicalReduction>
    </actuator>
  </transmission>
  <transmission name="katana_l_finger_trans">
    <type>transmission_interface/SimpleTransmission</type>
    <joint name="katana_l_finger_joint">
      <hardwareInterface>EffortJointInterface</hardwareInterface>
    </joint>
    <actuator name="katana_l_finger_motor">
      <hardwareInterface>EffortJointInterface</hardwareInterface>
      <mechanicalReduction>1</mechanicalReduction>
    </actuator>
  </transmission>
  <!-- **************************** -->
  <!-- ** base_link to base_frame * -->
  <!-- **************************** -->
  <!--xacro:include filename="$(find p2os_urdf)/defs/pioneer3dx.urdf.xacro" /-->
  <link name="base_link">
    <visual name="base_visual">
      <origin rpy="0 0 0" xyz="-0.045 0 0.148"/>
      <geometry name="pioneer_geom">
        <mesh filename="package://p2os_urdf/meshes/p3dx_meshes/chassis.stl"/>
      </geometry>
      <material name="ChassisRed">
        <color rgba="0.851 0.0 0.0 1.0"/>
      </material>
    </visual>
  </link>
  <gazebo reference="base_link">
    <material value="Gazebo/Red"/>
  </gazebo>
  <joint name="base_top_joint" type="fixed">
    <origin rpy="0 0 0" xyz="-0.045 0 0.234"/>
    <parent link="base_link"/>
    <child link="top_plate"/>
  </joint>
  <link name="top_plate">
    <visual>
      <inertial>
        <mass value="0.01"/>
        <origin xyz="0 0 0"/>
        <inertia ixx="1" ixy="0" ixz="0" iyy="1" iyz="0" izz="1"/>
      </inertial>
      <origin rpy="0 0 0" xyz="0 0 0"/>
      <geometry name="top_geom">
        <mesh filename="package://p2os_urdf/meshes/p3dx_meshes/top.stl"/>
      </geometry>
      <material name="TopBlack">
        <color rgba="0.038 0.038 0.038 1.0"/>
      </material>
    </visual>
  </link>
  <gazebo reference="top_plate">
    <material value="Gazebo/Black"/>
  </gazebo>
  <joint name="base_swivel_joint" type="continuous">
    <origin rpy="0 0 0" xyz="-0.185 0 0.055"/>
    <anchor xyz="0 0 0"/>
    <limit effort="100" k_velocity="0" velocity="100"/>
    <joint_properties damping="0.0" friction="0.0"/>
    <parent link="base_link"/>
    <child link="swivel"/>
  </joint>
  <link name="swivel">
    <inertial>
      <mass value="0.1"/>
      <origin xyz="0 0 0"/>
      <inertia ixx="0.01" ixy="0" ixz="0" iyy="0.01" iyz="0" izz="0.01"/>
    </inertial>
    <visual name="base_visual">
      <origin rpy="0 0 0" xyz="0 0 0"/>
      <geometry name="pioneer_geom">
        <mesh filename="package://p2os_urdf/meshes/p3dx_meshes/swivel.stl"/>
      </geometry>
      <material name="swivel">
        <color rgba="0.5 0.5 0.5 1"/>
      </material>
    </visual>
    <collision>
      <origin rpy="0 0 0" xyz="0 0 0"/>
      <geometry>
        <box size="0 0 0"/>
      </geometry>
    </collision>
  </link>
  <gazebo reference="swivel">
    <material value="Gazebo/Grey"/>
  </gazebo>
  <link name="center_hubcap">
    <inertial>
      <mass value="0.01"/>
      <origin xyz="0 0 0"/>
      <inertia ixx="0.012411765597" ixy="-0.000711733678" ixz="0.00050272983" iyy="0.015218160428" iyz="-0.000004273467" izz="0.011763977943"/>
    </inertial>
    <visual name="base_visual">
      <origin rpy="0 0 0" xyz="0 0 0"/>
      <geometry name="pioneer_geom">
        <mesh filename="package://p2os_urdf/meshes/p3dx_meshes/center_hubcap.stl"/>
      </geometry>
      <material name="swivel">
        <color rgba="0.5 0.5 0.5 1"/>
      </material>
    </visual>
    <collision>
      <origin rpy="0 0 0" xyz="0 0 0"/>
      <geometry>
        <box size="0 0 0"/>
      </geometry>
    </collision>
  </link>
  <gazebo reference="center_hubcap">
    <material value="Gazebo/Grey"/>
  </gazebo>
  <joint name="swivel_hubcap_joint" type="continuous">
    <origin rpy="0 0 0" xyz="-0.026 0 -0.016"/>
    <axis xyz="0 1 0"/>
    <anchor xyz="0 0 0"/>
    <limit effort="100" k_velocity="0" velocity="100"/>
    <joint_properties damping="0.0" friction="0.0"/>
    <parent link="swivel"/>
    <child link="center_wheel"/>
  </joint>
  <link name="center_wheel">
    <inertial>
      <mass value="0.1"/>
      <origin xyz="0 0 0"/>
      <inertia ixx="0.012411765597" ixy="-0.000711733678" ixz="0.00050272983" iyy="0.015218160428" iyz="-0.000004273467" izz="0.011763977943"/>
    </inertial>
    <visual name="base_visual">
      <origin rpy="0 0 0" xyz="0 0 0"/>
      <geometry name="pioneer_geom">
        <mesh filename="package://p2os_urdf/meshes/p3dx_meshes/center_wheel.stl"/>
      </geometry>
      <material name="WheelBlack">
        <color rgba="0.117 0.117 0.117 1"/>
      </material>
    </visual>
    <collision>
      <origin rpy="-1.57079635 0 0" xyz="0 0 0"/>
      <geometry>
        <!--<mesh filename="package://p2os_urdf/meshes/p3dx_meshes/center_wheel.stl"/>-->
        <cylinder length="0.01" radius="0.0375"/>
      </geometry>
    </collision>
  </link>
  <gazebo reference="left_hub">
    <material value="Gazebo/Yellow"/>
  </gazebo>
  <joint name="center_wheel_joint" type="fixed">
    <origin rpy="0 0 0" xyz="-0.0035 0 -0.001"/>
    <parent link="center_wheel"/>
    <child link="center_hubcap"/>
  </joint>
  <link name="left_hub">
    <visual>
      <origin rpy="0 0 0" xyz="0 0 0"/>
      <geometry>
        <mesh filename="package://p2os_urdf/meshes/p3dx_meshes/left_hubcap.stl"/>
      </geometry>
      <material name="HubcapYellow">
        <color rgba="1.0 0.811 0.151 1.0"/>
      </material>
    </visual>
  </link>
  <joint name="left_hub_joint" type="fixed">
    <origin rpy="0 0 0" xyz="0 0.15 0.08"/>
    <parent link="base_link"/>
    <child link="left_hub"/>
    <axis xyz="0 1 0"/>
  </joint>
  <link name="left_wheel_joint">
    <visual>
      <origin rpy="0 0 0" xyz="0 0 0"/>
      <geometry>
        <mesh filename="package://p2os_urdf/meshes/p3dx_meshes/left_wheel.stl"/>
      </geometry>
      <material name="WheelBlack">
        <color rgba="0.117 0.117 0.117 1"/>
      </material>
    </visual>
  </link>
  <joint name="left_wheel_joint" type="fixed">
    <origin rpy="0 0 0" xyz="0 0 0"/>
    <parent link="left_hub"/>
    <child link="left_wheel_joint"/>
  </joint>
  <gazebo reference="left_wheel_joint">
    <material value="Gazebo/Black"/>
  </gazebo>
  <link name="right_hub">
    <visual>
      <origin rpy="0 0 0" xyz="0 0 0"/>
      <geometry>
        <mesh filename="package://p2os_urdf/meshes/p3dx_meshes/right_hubcap.stl"/>
      </geometry>
      <material name="HubcapYellow">
        <color rgba="1.0 0.811 0.151 1.0"/>
      </material>
    </visual>
  </link>
  <gazebo reference="right_hub">
    <material value="Gazebo/Yellow"/>
  </gazebo>
  <joint name="right_hub_joint" type="fixed">
    <origin rpy="0 0 0" xyz="0 -0.15 0.08"/>
    <parent link="base_link"/>
    <child link="right_hub"/>
    <axis xyz="0 1 0"/>
  </joint>
  <link name="right_wheel_joint">
    <visual>
      <origin rpy="0 0 0" xyz="0 0 0"/>
      <geometry>
        <mesh filename="package://p2os_urdf/meshes/p3dx_meshes/right_wheel.stl"/>
      </geometry>
      <material name="WheelBlack">
        <color rgba="0.117 0.117 0.117 1"/>
      </material>
    </visual>
  </link>
  <joint name="right_wheel_joint" type="fixed">
    <origin rpy="0 0 0" xyz="0 0 0"/>
    <parent link="right_hub"/>
    <child link="right_wheel_joint"/>
  </joint>
  <gazebo reference="right_wheel_joint">
    <material value="Gazebo/Black"/>
  </gazebo>
  <link name="front_sonar">
    <inertial>
      <mass value="0.0001"/>
      <origin xyz="0 0 0"/>
      <inertia ixx="1" ixy="0" ixz="0" iyy="1" iyz="0" izz="1"/>
    </inertial>
    <visual name="base_visual">
      <origin rpy="0 0 0" xyz="0 0 0"/>
      <geometry name="pioneer_geom">
        <mesh filename="package://p2os_urdf/meshes/p3dx_meshes/front_sonar.stl"/>
      </geometry>
      <material name="SonarYellow">
        <color rgba="0.715 0.583 0.210 1.0"/>
      </material>
    </visual>
    <collision>
      <origin rpy="0 0 0" xyz="0 0 0"/>
      <geometry>
        <box size="0 0 0"/>
      </geometry>
    </collision>
  </link>
  <gazebo reference="front_sonar">
    <material value="Gazebo/Yellow"/>
  </gazebo>
  <joint name="base_front_joint" type="fixed">
    <origin rpy="0 0 0" xyz="-0.198 0 0.208"/>
    <parent link="base_link"/>
    <child link="front_sonar"/>
  </joint>
  <link name="back_sonar">
    <inertial>
      <mass value="0.0001"/>
      <origin xyz="0 0 0"/>
      <inertia ixx="1" ixy="0" ixz="0" iyy="1" iyz="0" izz="1"/>
    </inertial>
    <visual name="back_sonar_vis">
      <origin rpy="0 0 0" xyz="0 0 0"/>
      <geometry name="pioneer_geom">
        <mesh filename="package://p2os_urdf/meshes/p3dx_meshes/back_sonar.stl"/>
      </geometry>
      <material name="SonarYellow">
        <color rgba="0.715 0.583 0.210 1.0"/>
      </material>
    </visual>
    <collision>
      <origin rpy="0 0 0" xyz="0 0 0"/>
      <geometry>
        <box size="0 0 0"/>
      </geometry>
    </collision>
  </link>
  <gazebo reference="back_sonar">
    <material value="Gazebo/Yellow"/>
  </gazebo>
  <joint name="base_back_joint" type="fixed">
    <origin rpy="0 0 0" xyz="0.109 0 0.209"/>
    <parent link="base_link"/>
    <child link="back_sonar"/>
  </joint>
  <link name="base_frame">
    <visual>
      <origin rpy="0 0 0" xyz="0 0 0"/>
      <geometry>
        <mesh filename="package://hsmakata_description/meshes/base_frame.stl"/>
      </geometry>
      <material name="grey">
        <color rgba="0.3 0.3 0.3 1"/>
      </material>
    </visual>
    <collision>
      <geometry>
        <mesh filename="package://hsmakata_description/meshes/base_frame_collision.stl"/>
      </geometry>
    </collision>
  </link>
  <joint name="base_frame_joint" type="fixed">
    <parent link="top_plate"/>
    <child link="base_frame"/>
    <origin rpy="0 0 0" xyz="0.0 0.0 0.002"/>
  </joint>
  <!-- **************************** -->
  <!-- * dummy_link to sick_link ** -->
  <!-- **************************** -->
  <joint name="sick_joint" type="fixed">
    <parent link="top_plate"/>
    <child link="sick_link"/>
    <origin rpy="0 0 0" xyz="0.12 0 0.07"/>
  </joint>
  <link name="sick_link">
    <visual>
      <geometry>
        <mesh filename="package://hsmakata_description/meshes/sick_lms200.stl"/>
      </geometry>
      <material name="blue">
        <color rgba="0.0 0.0 0.8 1"/>
      </material>
    </visual>
  </link>
  <!-- **************************** -->
  <!-- * dummy_link to kata_plate_link * -->
  <!-- **************************** -->
  <link name="kata_plate_link">
    <visual>
      <geometry>
        <mesh filename="package://hsmakata_description/meshes/katana_base_plate.stl"/>
      </geometry>
      <material name="grey">
        <color rgba="0.5 0.5 0.5 1"/>
      </material>
    </visual>
  </link>
  <joint name="kata_plate_joint" type="fixed">
    <parent link="top_plate"/>
    <child link="kata_plate_link"/>
    <origin rpy="0 0 0" xyz="0.022 0 0.191"/>
  </joint>
  <!-- **************************** -->
  <!-- *** kata_plate_link to Katana Arm *** -->
  <!-- **************************** -->
  <transmission name="katana_motor1_pan_trans">
    <type>transmission_interface/SimpleTransmission</type>
    <joint name="katana_motor1_pan_joint">
      <hardwareInterface>EffortJointInterface</hardwareInterface>
    </joint>
    <actuator name="katana_motor1_pan_motor">
      <hardwareInterface>EffortJointInterface</hardwareInterface>
      <mechanicalReduction>1</mechanicalReduction>
    </actuator>
  </transmission>
  <transmission name="katana_motor2_lift_trans">
    <type>transmission_interface/SimpleTransmission</type>
    <joint name="katana_motor2_lift_joint">
      <hardwareInterface>EffortJointInterface</hardwareInterface>
    </joint>
    <actuator name="katana_motor2_lift_motor">
      <hardwareInterface>EffortJointInterface</hardwareInterface>
      <mechanicalReduction>1</mechanicalReduction>
    </actuator>
  </transmission>
  <transmission name="katana_motor3_lift_trans">
    <type>transmission_interface/SimpleTransmission</type>
    <joint name="katana_motor3_lift_joint">
      <hardwareInterface>EffortJointInterface</hardwareInterface>
    </joint>
    <actuator name="katana_motor3_lift_motor">
      <hardwareInterface>EffortJointInterface</hardwareInterface>
      <mechanicalReduction>1</mechanicalReduction>
    </actuator>
  </transmission>
  <transmission name="katana_motor4_lift_trans">
    <type>transmission_interface/SimpleTransmission</type>
    <joint name="katana_motor4_lift_joint">
      <hardwareInterface>EffortJointInterface</hardwareInterface>
    </joint>
    <actuator name="katana_motor4_lift_motor">
      <hardwareInterface>EffortJointInterface</hardwareInterface>
      <mechanicalReduction>1</mechanicalReduction>
    </actuator>
  </transmission>
  <transmission name="katana_motor5_wrist_roll_trans">
    <type>transmission_interface/SimpleTransmission</type>
    <joint name="katana_motor5_wrist_roll_joint">
      <hardwareInterface>EffortJointInterface</hardwareInterface>
    </joint>
    <actuator name="katana_motor5_wrist_roll_motor">
      <hardwareInterface>EffortJointInterface</hardwareInterface>
      <mechanicalReduction>1</mechanicalReduction>
    </actuator>
  </transmission>
  <transmission name="katana_r_finger_trans">
    <type>transmission_interface/SimpleTransmission</type>
    <joint name="katana_r_finger_joint">
      <hardwareInterface>EffortJointInterface</hardwareInterface>
    </joint>
    <actuator name="katana_r_finger_motor">
      <hardwareInterface>EffortJointInterface</hardwareInterface>
      <mechanicalReduction>1</mechanicalReduction>
    </actuator>
  </transmission>
  <transmission name="katana_l_finger_trans">
    <type>transmission_interface/SimpleTransmission</type>
    <joint name="katana_l_finger_joint">
      <hardwareInterface>EffortJointInterface</hardwareInterface>
    </joint>
    <actuator name="katana_l_finger_motor">
      <hardwareInterface>EffortJointInterface</hardwareInterface>
      <mechanicalReduction>1</mechanicalReduction>
    </actuator>
  </transmission>
  <gazebo>
    <plugin filename="libgazebo_ros_control.so" name="gazebo_ros_control">
      <robotSimType>gazebo_ros_control/DefaultRobotHWSim</robotSimType>
    </plugin>
    <!-- gripper controller -->
    <plugin filename="libgazebo_ros_katana_gripper.so" name="katana_gripper_controller">
      <alwaysOn>true</alwaysOn>
      <node_namespace>katana</node_namespace>
      <r_finger_joint>katana_r_finger_joint</r_finger_joint>
      <l_finger_joint>katana_l_finger_joint</l_finger_joint>
      <updateRate>1000.0</updateRate>
      <max_torque>0.5</max_torque>
    </plugin>
    <!-- a formal implementation of grasp hack in gazebo with fixed joint -->
    <gripper name="katana_gripper_grasp_hack">
      <grasp_check>
        <attach_steps>20</attach_steps>
        <detach_steps>40</detach_steps>
        <min_contact_count>2</min_contact_count>
      </grasp_check>
      <gripper_link>katana_r_finger_link</gripper_link>
      <gripper_link>katana_l_finger_link</gripper_link>
      <palm_link>katana_gripper_link</palm_link>
    </gripper>
  </gazebo>
  <gazebo reference="katana_base_link">
    <material value="Gazebo/Grey"/>
  </gazebo>
  <gazebo reference="katana_motor1_pan_link">
    <material value="Gazebo/Grey"/>
    <turnGravityOff>true</turnGravityOff>
  </gazebo>
  <gazebo reference="katana_motor2_lift_link">
    <material value="Gazebo/Grey"/>
    <turnGravityOff>true</turnGravityOff>
  </gazebo>
  <gazebo reference="katana_motor3_lift_link">
    <material value="Gazebo/Grey"/>
    <turnGravityOff>true</turnGravityOff>
  </gazebo>
  <gazebo reference="katana_motor4_lift_link">
    <material value="Gazebo/Grey"/>
    <turnGravityOff>true</turnGravityOff>
  </gazebo>
  <gazebo reference="katana_motor5_wrist_roll_link">
    <material value="Gazebo/Grey"/>
    <turnGravityOff>true</turnGravityOff>
  </gazebo>
  <gazebo reference="katana_gripper_link">
    <material value="Gazebo/Grey"/>
    <turnGravityOff>true</turnGravityOff>
  </gazebo>
  <gazebo reference="katana_r_finger_link">
    <material value="Gazebo/Grey"/>
    <turnGravityOff>true</turnGravityOff>
  </gazebo>
  <gazebo reference="katana_l_finger_link">
    <material value="Gazebo/Grey"/>
    <turnGravityOff>true</turnGravityOff>
  </gazebo>
  <gazebo reference="katana_motor1_pan_joint">
    <initial_joint_position>-3.022</initial_joint_position>
  </gazebo>
  <gazebo reference="katana_motor2_lift_joint">
    <initial_joint_position>2.163</initial_joint_position>
  </gazebo>
  <gazebo reference="katana_motor3_lift_joint">
    <initial_joint_position>-2.207</initial_joint_position>
  </gazebo>
  <gazebo reference="katana_motor4_lift_joint">
    <initial_joint_position>-2.026</initial_joint_position>
  </gazebo>
  <gazebo reference="katana_motor5_wrist_roll_joint">
    <initial_joint_position>-2.990</initial_joint_position>
  </gazebo>
  <gazebo reference="katana_r_finger_joint">
    <initial_joint_position>0.3</initial_joint_position>
  </gazebo>
  <gazebo reference="katana_l_finger_joint">
    <initial_joint_position>0.3</initial_joint_position>
  </gazebo>
  <link name="katana_base_link">
    <visual>
      <origin rpy="0 0 0" xyz="0 0 0"/>
      <geometry>
        <mesh filename="package://katana_description/meshes/katana/katana_base_link.stl"/>
      </geometry>
      <material name="grey">
        <color rgba="0.8 0.8 0.8 1"/>
      </material>
    </visual>
    <collision>
      <origin rpy="0 0 0" xyz="0 0 0"/>
      <geometry>
        <mesh filename="package://katana_description/meshes/katana/convex/katana_base_link_convex.stl"/>
      </geometry>
    </collision>
    <inertial>
      <mass value="1.4047990875"/>
      <origin xyz="-0.000327 0.000908 0.058457"/>
      <inertia ixx="0.003000703" ixy="0.000000864" ixz="-0.000011312" iyy="0.002974822" iyz="0.000036294" izz="0.001434739"/>
    </inertial>
  </link>
  <joint name="katana_motor1_pan_joint" type="revolute">
    <!-- Joint 1 in Katana Manual -->
    <parent link="katana_base_link"/>
    <child link="katana_motor1_pan_link"/>
    <origin rpy="0 0 0" xyz="0 0 0.2015"/>
    <axis xyz="0 0 1"/>
    <limit effort="1.5" lower="-3.025528" upper="2.891097" velocity="2.208932"/>
  </joint>
  <link name="katana_motor1_pan_link">
    <visual>
      <origin rpy="0 0 0" xyz="0 0 -0.2015"/>
      <geometry>
        <mesh filename="package://katana_description/meshes/katana/katana_motor1_pan_link.stl"/>
      </geometry>
      <material name="grey"/>
    </visual>
    <collision>
      <origin rpy="0 0 0" xyz="0 0 -0.2015"/>
      <geometry>
        <mesh filename="package://katana_description/meshes/katana/convex/katana_motor1_pan_link_convex.stl"/>
      </geometry>
    </collision>
    <inertial>
      <mass value="0.74793301875"/>
      <origin xyz="-0.000410 -0.001285 -0.016774"/>
      <inertia ixx="0.001737241" ixy="0.000000421" ixz="0.000000650" iyy="0.000998782" iyz="0.000016114" izz="0.001349170"/>
    </inertial>
  </link>
  <joint name="katana_motor2_lift_joint" type="revolute">
    <!-- Joint 2 in Katana Manual -->
    <parent link="katana_motor1_pan_link"/>
    <child link="katana_motor2_lift_link"/>
    <origin rpy="1.57079632679 0 0" xyz="0 0 0"/>
    <axis xyz="0 0 1"/>
    <limit effort="0.6" lower="-0.135228" upper="2.168572" velocity="1.190799"/>
  </joint>
  <link name="katana_motor2_lift_link">
    <visual>
      <origin rpy="-1.57079632679 0 0" xyz="0 0 0"/>
      <geometry>
        <mesh filename="package://katana_description/meshes/katana/katana_motor2_lift_link.stl"/>
      </geometry>
      <!-- <geometry>
          <cylinder length="${link2_length}" radius="0.02"/>
        </geometry>
        <origin rpy="0 ${-M_PI/2} 0" xyz="${link2_length/2} 0 0" /> -->
      <material name="grey"/>
    </visual>
    <collision>
      <origin rpy="-1.57079632679 0 0" xyz="0 0 0"/>
      <geometry>
        <mesh filename="package://katana_description/meshes/katana/convex/katana_motor2_lift_link_convex.stl"/>
      </geometry>
    </collision>
    <inertial>
      <mass value="0.80174941875"/>
      <origin xyz="0.092420 0.005283 0.000172"/>
      <inertia ixx="0.000478252" ixy="0.000081166" ixz="0.000003961" iyy="0.004314636" iyz="0.000000332" izz="0.004625444"/>
    </inertial>
  </link>
  <joint name="katana_motor3_lift_joint" type="revolute">
    <!-- Joint 3 in Katana Manual -->
    <parent link="katana_motor2_lift_link"/>
    <child link="katana_motor3_lift_link"/>
    <origin rpy="0 0 0" xyz="0.19 0 0"/>
    <axis xyz="0 0 1"/>
    <!-- unexplicably, the measured velocity limit of this motor is exactly half of what vel_enc2rad(180) says -->
    <limit effort="0.25" lower="-2.221804" upper="2.054223" velocity="1.190799"/>
  </joint>
  <link name="katana_motor3_lift_link">
    <visual>
      <origin rpy="-1.57079632679 0 0" xyz="0 0 0"/>
      <geometry>
        <mesh filename="package://katana_description/meshes/katana/katana_motor3_lift_link.stl"/>
      </geometry>
      <!--<geometry>
          <cylinder length="${link3_length}" radius="0.02"/>
        </geometry>
        <origin rpy="0 ${-M_PI/2} 0" xyz="${link3_length/2} 0 0" />-->
      <material name="grey"/>
    </visual>
    <collision>
      <origin rpy="-1.57079632679 0 0" xyz="0 0 0"/>
      <geometry>
        <mesh filename="package://katana_description/meshes/katana/convex/katana_motor3_lift_link_convex.stl"/>
      </geometry>
    </collision>
    <inertial>
      <mass value="0.79241664375"/>
      <origin xyz="0.058036 0.008963 -0.000187"/>
      <inertia ixx="0.001156089" ixy="0.000112877" ixz="-0.000004398" iyy="0.002305646" iyz="-0.000000036" izz="0.003128648"/>
    </inertial>
  </link>
  <joint name="katana_motor4_lift_joint" type="revolute">
    <!-- Joint 4 in Katana Manual -->
    <parent link="katana_motor3_lift_link"/>
    <child link="katana_motor4_lift_link"/>
    <origin rpy="3.14159265359 0 0" xyz="0.139 0 0"/>
    <axis xyz="0 0 1"/>
    <limit effort="0.1" lower="-2.033309" upper="1.876133" velocity="2.208932"/>
  </joint>
  <link name="katana_motor4_lift_link">
    <visual>
      <origin rpy="1.57079632679 0 0" xyz="0 0 0"/>
      <geometry>
        <mesh filename="package://katana_description/meshes/katana/katana_motor4_lift_link.stl"/>
      </geometry>
      <!-- <geometry>
          <cylinder length="${link4_length}" radius="0.02"/>
        </geometry>
        <origin rpy="0 ${-M_PI/2} 0" xyz="${link4_length/2} 0 0" /> -->
      <material name="grey"/>
    </visual>
    <collision>
      <origin rpy="1.57079632679 0 0" xyz="0 0 0"/>
      <geometry>
        <mesh filename="package://katana_description/meshes/katana/convex/katana_motor4_lift_link_convex.stl"/>
      </geometry>
    </collision>
    <inertial>
      <mass value="0.69149323125"/>
      <origin xyz="0.050401 0.005807 0.000000"/>
      <inertia ixx="0.000765999" ixy="0.000045260" ixz="-0.000001210" iyy="0.001504115" iyz="0.000000147" izz="0.001887277"/>
    </inertial>
  </link>
  <joint name="katana_motor5_wrist_roll_joint" type="revolute">
    <!-- Joint 5 in Katana Manual -->
    <parent link="katana_motor4_lift_link"/>
    <child link="katana_motor5_wrist_roll_link"/>
    <origin rpy="1.57079632679 0 -1.57079632679" xyz="0.1523 0 0"/>
    <axis xyz="0 0 1"/>
    <limit effort="0.01" lower="-2.993240" upper="2.870985" velocity="2.208932"/>
  </joint>
  <link name="katana_motor5_wrist_roll_link">
    <visual>
      <origin rpy="0 3.14159265359 0" xyz="0 0 0"/>
      <geometry>
        <mesh filename="package://katana_description/meshes/katana/katana_motor5_wrist_roll_link.stl"/>
      </geometry>
      <!--<geometry>
          <cylinder length="${link5_length}" radius="0.02"/>
        </geometry>
        <origin rpy="0 ${-M_PI/2} 0" xyz="${link5_length/2} 0 0" />-->
      <material name="grey"/>
    </visual>
    <collision>
      <origin rpy="0 3.14159265359 0" xyz="0 0 0"/>
      <geometry>
        <mesh filename="package://katana_description/meshes/katana/convex/katana_motor5_wrist_roll_link_convex.stl"/>
      </geometry>
    </collision>
    <inertial>
      <mass value="0.25622555625"/>
      <origin xyz="-0.003140899 0.000013920 0.001680144"/>
      <inertia ixx="0.000120481" ixy="0.000000015" ixz="-0.000001089" iyy="0.000132130" iyz="-0.000000124" izz="0.000093522"/>
    </inertial>
  </link>
  <joint name="katana_gripper_joint" type="fixed">
    <parent link="katana_motor5_wrist_roll_link"/>
    <child link="katana_gripper_link"/>
    <origin rpy="0 1.57079632679 0" xyz="0 0 -0.0323"/>
  </joint>
  <link name="katana_gripper_link">
    <visual>
      <origin rpy="0 3.14159265359 0" xyz="0 0 0"/>
      <geometry>
        <mesh filename="package://katana_description/meshes/katana/katana_gripper_link.stl"/>
      </geometry>
      <material name="grey"/>
    </visual>
    <collision>
      <origin rpy="0 3.14159265359 0" xyz="0 0 0"/>
      <geometry>
        <mesh filename="package://katana_description/meshes/katana/convex/katana_gripper_link_convex.stl"/>
      </geometry>
    </collision>
    <inertial>
      <mass value="0.0552136183596"/>
      <origin xyz="-0.014379 -0.000000 0.000006"/>
      <inertia ixx="0.000011468" ixy="0.000000000" ixz="0.000000007" iyy="0.000013830" iyz="0.000000000" izz="0.000011290"/>
    </inertial>
  </link>
  <joint name="katana_r_finger_joint" type="revolute">
    <parent link="katana_gripper_link"/>
    <child link="katana_r_finger_link"/>
    <origin rpy="0 0 0" xyz="0.034 0 0"/>
    <axis xyz="0 0 1"/>
    <limit effort="0.5" lower="-0.44" upper="0.30" velocity="0.718834"/>
  </joint>
  <link name="katana_r_finger_link">
    <visual>
      <origin rpy="0 3.14159265359 0" xyz="0 0 0"/>
      <geometry>
        <mesh filename="package://katana_description/meshes/katana/katana_gripper_r_finger.stl"/>
      </geometry>
      <material name="grey"/>
    </visual>
    <collision>
      <origin rpy="0 3.14159265359 0" xyz="0 0 0"/>
      <geometry>
        <mesh filename="package://katana_description/meshes/katana/convex/katana_gripper_r_finger_convex.stl"/>
      </geometry>
    </collision>
    <inertial>
      <mass value="0.0251722230462"/>
      <origin xyz="0.001784 0.025167 -.001603"/>
      <inertia ixx="0.000005990" ixy="0.000008473" ixz="0.000001448" iyy="0.000019757" iyz="-0.000000996" izz="0.000023588"/>
    </inertial>
  </link>
  <joint name="katana_l_finger_joint" type="revolute">
    <parent link="katana_gripper_link"/>
    <child link="katana_l_finger_link"/>
    <origin rpy="3.14159265359 0 0" xyz="0.034 0 0"/>
    <axis xyz="0 0 1"/>
    <limit effort="0.5" lower="-0.44" upper="0.30" velocity="0.718834"/>
  </joint>
  <link name="katana_l_finger_link">
    <visual>
      <origin rpy="0 3.14159265359 0" xyz="0 0 0"/>
      <geometry>
        <mesh filename="package://katana_description/meshes/katana/katana_gripper_l_finger.stl"/>
      </geometry>
      <material name="grey"/>
    </visual>
    <collision>
      <origin rpy="0 3.14159265359 0" xyz="0 0 0"/>
      <geometry>
        <mesh filename="package://katana_description/meshes/katana/convex/katana_gripper_l_finger_convex.stl"/>
      </geometry>
    </collision>
    <inertial>
      <mass value="0.0251722230462"/>
      <origin xyz="0.001784 0.025167 -.001603"/>
      <inertia ixx="0.000005990" ixy="0.000008473" ixz="0.000001448" iyy="0.000019757" iyz="-0.000000996" izz="0.000023588"/>
    </inertial>
  </link>
  <joint name="katana_gripper_tool_frame_joint" type="fixed">
    <parent link="katana_motor5_wrist_roll_link"/>
    <child link="katana_gripper_tool_frame"/>
    <origin rpy="0 1.57079632679 0" xyz="0 0 -0.1505"/>
  </joint>
  <link name="katana_gripper_tool_frame">
    <!-- This is the coordinate system of the tool (this is the position
         used in IK etc., relative to the base frame); there is no actual
         arm part attached to this link -->
  </link>
  <joint name="katana_base_frame_joint" type="fixed">
    <parent link="katana_base_link"/>
    <child link="katana_base_frame"/>
    <origin rpy="0 0 0" xyz="0 0 0.2015"/>
  </joint>
  <link name="katana_base_frame">
    <!-- This is the reference coordinate system of the arm (the KNI kinematics are specified
         in this frame); there is no actual arm part attached to this link -->
  </link>
  <joint name="base_link_to_katana" type="fixed">
    <parent link="kata_plate_link"/>
    <child link="katana_base_link"/>
    <origin rpy="0 0 0" xyz="0 0 0.012"/>
  </joint>
  <!-- **************************** -->
  <!-- ***** dummy_link to pole_link** -->
  <!-- **************************** -->
  <link name="pole_link">
    <visual>
      <geometry>
        <mesh filename="package://hsmakata_description/meshes/pole.stl"/>
      </geometry>
      <material name="grey">
        <color rgba="0.5 0.5 0.5 1"/>
      </material>
    </visual>
    <collision>
      <geometry>
        <mesh filename="package://hsmakata_description/meshes/pole_collision.stl"/>
      </geometry>
    </collision>
  </link>
  <joint name="pole_joint" type="fixed">
    <parent link="top_plate"/>
    <child link="pole_link"/>
    <origin rpy="0 0 0" xyz="-0.195 0.0 0.0"/>
  </joint>
  <!-- **************************** -->
  <!-- ***** pole_link to pole_top_link** -->
  <!-- **************************** -->
  <link name="pole_top_link"/>
  <joint name="pole_top_joint" type="fixed">
    <parent link="pole_link"/>
    <child link="pole_top_link"/>
    <origin rpy="0 0 0" xyz="0.0 0.0 0.966"/>
  </joint>
  <!-- **************************** -->
  <!-- ***** pole_top_link to kinect_holder_link ** -->
  <!-- **************************** -->
  <link name="kinect_cube_link">
    <visual>
      <origin rpy="0 0 0" xyz="0 0 0"/>
      <geometry>
        <box size="0.11 0.08 0.065"/>
      </geometry>
      <material name="orange">
        <color rgba="0.8 0.22 0.0 1"/>
      </material>
    </visual>
    <collision>
      <geometry>
        <box size="0.12 0.09 0.07"/>
      </geometry>
    </collision>
  </link>
  <joint name="kinect_cube_joint" type="fixed">
    <parent link="pole_top_link"/>
    <child link="kinect_cube_link"/>
    <origin rpy="0 0 0" xyz="0.04 0.0 0.0"/>
  </joint>
  <!-- **************************** -->
  <!-- ***** kinect_outer_frame_link to kinect_link ** -->
  <!-- **************************** -->
  <link name="kinect_outer_frame_link">
    <visual>
      <origin rpy="0 0 0" xyz="0 0 0"/>
      <geometry>
        <mesh filename="package://hsmakata_description/meshes/kinect_outer_frame.stl"/>
      </geometry>
      <material name="grey">
        <color rgba="0.5 0.5 0.5 1"/>
      </material>
    </visual>
  </link>
  <joint name="kinect_yaw_joint" type="revolute">
    <parent link="kinect_cube_link"/>
    <child link="kinect_outer_frame_link"/>
    <origin rpy="0 0 0" xyz="0.018 0.0 0.0375"/>
    <axis xyz="0 0 1"/>
    <limit effort="0.6" lower="-2.8" upper="2.8" velocity="1.0"/>
  </joint>
  <!-- **************************** -->
  <!-- ***** kinect_holder_link to kinect_link ** -->
  <!-- **************************** -->
  <link name="kinect_inner_frame_link">
    <visual>
      <origin rpy="0 0 0" xyz="0.0 0 0"/>
      <geometry>
        <mesh filename="package://hsmakata_description/meshes/kinect_frame.stl"/>
      </geometry>
    </visual>
    <collision>
      <origin rpy="0 0 0" xyz="-0.0315 0 -0.017"/>
      <geometry>
        <box size="0.0730 0.2760 0.0720"/>
      </geometry>
    </collision>
    <inertial>
      <mass value="0.43"/>
      <origin xyz="0 0 0"/>
      <inertia ixx="0.00291539883384" ixy="0.0" ixz="0.0" iyy="0.000376715682647" iyz="0.0" izz="0.0029205946651"/>
    </inertial>
  </link>
  <!-- kinect -25 effektiv 21.77 rad=0.38 -->
  <!-- origin rpy="0 0.38 0" xyz="0.06 -0.02 0.075" -->
  <joint name="kinect_pitch_joint" type="revolute">
    <parent link="kinect_outer_frame_link"/>
    <child link="kinect_inner_frame_link"/>
    <origin rpy="0 0 0" xyz="0 0 0.15"/>
    <axis xyz="0 1 0"/>
    <limit effort="1000.0" lower="-2.8" upper="2.8" velocity="1.0"/>
  </joint>
  <!-- **************************** -->
  <!-- ***** kinect_holder_link to kinect_link ** -->
  <!-- **************************** -->
  <link name="kinect_link">
  </link>
  <!-- kinect -25 effektiv 21.77 rad=0.38 -->
  <!-- origin rpy="0 0.38 0" xyz="0.06 -0.02 0.075" -->
  <joint name="kinect_joint" type="fixed">
    <parent link="kinect_inner_frame_link"/>
    <child link="kinect_link"/>
    <origin rpy="0 0 0" xyz="0.05 0 0 "/>
  </joint>
  <joint name="kinect_depth_joint" type="fixed">
    <origin rpy="0 0 0" xyz="0 -0.028 0"/>
    <parent link="kinect_link"/>
    <child link="kinect_depth_frame"/>
  </joint>
  <link name="kinect_depth_frame">
    <inertial>
      <mass value="0.000001"/>
      <origin xyz="0 0 0"/>
      <inertia ixx="0.0001" ixy="0.0" ixz="0.0" iyy="0.0001" iyz="0.0" izz="0.0001"/>
    </inertial>
  </link>
  <joint name="kinect_depth_optical_joint" type="fixed">
    <origin rpy="-1.57079632679 0 -1.57079632679" xyz="0 0 0"/>
    <parent link="kinect_depth_frame"/>
    <child link="kinect_depth_optical_frame"/>
  </joint>
  <link name="kinect_depth_optical_frame">
    <inertial>
      <mass value="0.000001"/>
      <origin xyz="0 0 0"/>
      <inertia ixx="0.0001" ixy="0.0" ixz="0.0" iyy="0.0001" iyz="0.0" izz="0.0001"/>
    </inertial>
  </link>
  <joint name="kinect_rgb_joint" type="fixed">
    <origin rpy="0 0 0" xyz="0 -0.005 0"/>
    <parent link="kinect_link"/>
    <child link="kinect_rgb_frame"/>
  </joint>
  <link name="kinect_rgb_frame">
    <inertial>
      <mass value="0.000001"/>
      <origin xyz="0 0 0"/>
      <inertia ixx="0.0001" ixy="0.0" ixz="0.0" iyy="0.0001" iyz="0.0" izz="0.0001"/>
    </inertial>
  </link>
  <joint name="kinect_rgb_optical_joint" type="fixed">
    <origin rpy="-1.57079632679 0 -1.57079632679" xyz="0 0 0"/>
    <parent link="kinect_rgb_frame"/>
    <child link="kinect_rgb_optical_frame"/>
  </joint>
  <link name="kinect_rgb_optical_frame">
    <inertial>
      <mass value="0.000001"/>
      <origin xyz="0 0 0"/>
      <inertia ixx="0.0001" ixy="0.0" ixz="0.0" iyy="0.0001" iyz="0.0" izz="0.0001"/>
    </inertial>
  </link>
</robot>

